Workbook

Sheet Leeme
A1: Caso Flow · Modelo financiero a 3 años (+ años 4–5 en run-rate)
A3: Cómo usarlo
A4: 1. Elija el escenario en Supuestos!C3 (A, B o C). Toda la hoja Modelo se recalcula.
A5: 2. Azul = supuesto editable · Negro = fórmula · Verde = vínculo a otra hoja · Amarillo = supuestos clave (los 3 de mayor sensibilidad).
A6: 3. Cada supuesto indica su fuente: 'Data room' (dato del caso) o 'Supuesto' (declarado por el candidato, a validar).
A7: 4. Sensibilidad: cada fila aplica un multiplicador a un grupo de supuestos sobre el escenario seleccionado (mismo motor que Modelo).
A8: 5. DataRoom: cálculos reproducibles de las tablas A–F (funnel, ANPR ponderado, facial, disputas, costos).
A10: Escenarios
A11: A · Plan directivo: 6 islas Flow por estación, 420 estaciones en el año 1.
A12: B · Escalonado: 2 islas Flow (carriles exprés) por estación, 120 → 300 → 420 estaciones.
A13: C · Recomendado: 2 islas Flow, solo estaciones priorizadas por tráfico y flotas, 120 → 200 → 250.
A15: País del modelo: Colombia (COP). Perú requiere un caso propio en PEN (ticket, margen, MDR, impuestos, costos) antes de abrir estaciones allí; ver hoja Localizacion.
... A17: Las cifras del caso son ficticias. Los supuestos propios están marcados y deben validarse con Finanzas, Operaciones y proveedores.

Sheet Supuestos
A1: Supuestos del caso de negocio
A3: Escenario seleccionado | C3: C | D3: =MATCH(C3,{"A","B","C"},0) -> 3 | E3: ← índice del escenario
A5: Parámetro | B5: Unidad | C5: A · Directivo | D5: B · Escalonado | E5: C · Recomendado | F5: Seleccionado | G5: Fuente / nota
A6: FX COP por USD | B6: COP/USD | C6: 4000 | D6: 4000 | E6: 4000 | F6: =INDEX(C6:E6,$D$3) -> 4000 | G6: Supuesto (tasa de planeación)
A7: Ticket promedio | B7: COP | C7: 118000 | D7: 118000 | E7: 118000 | F7: =INDEX(C7:E7,$D$3) -> 118000 | G7: Data room, Tabla D
A8: Precio por galón | B8: COP/gal | C8: 16000 | D8: 16000 | E8: 16000 | F8: =INDEX(C8:E8,$D$3) -> 16000 | G8: Supuesto (precio de referencia)
A9: Margen bruto por galón | B9: USD/gal | C9: 0.21 | D9: 0.21 | E9: 0.21 | F9: =INDEX(C9:E9,$D$3) -> 0.21 | G9: Data room, Tabla F
A10: Tráfico por estación (base piloto) | B10: veh/día | C10: 245 | D10: 245 | E10: 245 | F10: =INDEX(C10:E10,$D$3) -> 245 | G10: Data room: 41.200 / 56 días / 3 estaciones
A11: Multiplicador de tráfico de estaciones elegidas | B11: x | C11: 1 | D11: 1 | E11: 1.8 | F11: =INDEX(C11:E11,$D$3) -> 1.8 | G11: Supuesto: estaciones priorizadas por tráfico vs. piloto. Validar con ventas por estación
A12: Días operativos al año | B12: días | C12: 365 | D12: 365 | E12: 365 | F12: =INDEX(C12:E12,$D$3) -> 365 | G12: Supuesto
A13: Islas Flow por estación | B13: islas | C13: 6 | D13: 2 | E13: 2 | F13: =INDEX(C13:E13,$D$3) -> 2 | G13: A: Data room (6 islas). B/C: carriles exprés, decisión del candidato
A14: Kit por isla | B14: USD | C14: 6800 | D14: 6800 | E14: 6800 | F14: =INDEX(C14:E14,$D$3) -> 6800 | G14: Data room, Tabla F
A15: Instalación y contingencia sobre kit | B15: % | C15: 0.1 | D15: 0.1 | E15: 0.1 | F15: =INDEX(C15:E15,$D$3) -> 0.1 | G15: Supuesto
A16: Integración POS legado por estación | B16: USD | C16: 9500 | D16: 9500 | E16: 9500 | F16: =INDEX(C16:E16,$D$3) -> 9500 | G16: Data room, Tabla F
A17: Integración POS cloud por estación | B17: USD | C17: 2000 | D17: 2000 | E17: 2000 | F17: =INDEX(C17:E17,$D$3) -> 2000 | G17: Data room, Tabla F
... A31: Estaciones Flow al inicio (piloto) | B31: est. | C31: 3 | D31: 3 | E31: 3 | F31: =INDEX(C31:E31,$D$3) -> 3 | G31: Data room
A33: Supuestos por año
A34: Parámetro | B34: Año | C34: A · Directivo | D34: B · Escalonado | E34: C · Recomendado | F34: Seleccionado | G34: Fuente / nota
A35: Estaciones al cierre | B35: Año 1 | C35: 420 | D35: 120 | E35: 120 | F35: =INDEX(C35:E35,$D$3) -> 120 | G35: Decisión de despliegue por escenario
A36: Estaciones al cierre | B36: Año 2 | C36: 420 | D36: 300 | E36: 200 | F36: =INDEX(C36:E36,$D$3) -> 200
A37: Estaciones al cierre | B37: Año 3 | C37: 420 | D37: 420 | E37: 250 | F37: =INDEX(C37:E37,$D$3) -> 250
A38: Nuevas estaciones con POS cloud | B38: Año 1 | C38: 60 | D38: 60 | E38: 60 | F38: =INDEX(C38:E38,$D$3) -> 60 | G38: Data room: 60 estaciones con POS cloud, primero
A39: Nuevas estaciones con POS cloud | B39: Año 2 | C39: 0 | D39: 0 | E39: 0 | F39: =INDEX(C39:E39,$D$3) -> 0
A40: Nuevas estaciones con POS cloud | B40: Año 3 | C40: 0 | D40: 0 | E40: 0 | F40: =INDEX(C40:E40,$D$3) -> 0
A41: Vehículos enrolados / tráfico | B41: Año 1 | C41: 0.2 | D41: 0.2 | E41: 0.2 | F41: =INDEX(C41:E41,$D$3) -> 0.2 | G41: Supuesto. Piloto: 16,7 % (Tabla A)
A42: Vehículos enrolados / tráfico | B42: Año 2 | C42: 0.3 | D42: 0.3 | E42: 0.3 | F42: =INDEX(C42:E42,$D$3) -> 0.3
A43: Vehículos enrolados / tráfico | B43: Año 3 | C43: 0.4 | D43: 0.4 | E43: 0.4 | F43: =INDEX(C43:E43,$D$3) -> 0.4
A44: Cierre sin intervención / enrolados | B44: Año 1 | C44: 0.7 | D44: 0.7 | E44: 0.7 | F44: =INDEX(C44:E44,$D$3) -> 0.7 | G44: Supuesto. Piloto: 64,2 % estimado (Tabla A)
A45: Cierre sin intervención / enrolados | B45: Año 2 | C45: 0.76 | D45: 0.76 | E45: 0.76 | F45: =INDEX(C45:E45,$D$3) -> 0.76
A46: Cierre sin intervención / enrolados | B46: Año 3 | C46: 0.8 | D46: 0.8 | E46: 0.8 | F46: =INDEX(C46:E46,$D$3) -> 0.8
A47: Volumen incremental por estación | B47: Año 1 | C47: 0.01 | D47: 0.01 | E47: 0.01 | F47: =INDEX(C47:E47,$D$3) -> 0.01 | G47: Supuesto CLAVE: no medido en el piloto (se mide en M6)
A48: Volumen incremental por estación | B48: Año 2 | C48: 0.02 | D48: 0.02 | E48: 0.02 | F48: =INDEX(C48:E48,$D$3) -> 0.02
A49: Volumen incremental por estación | B49: Año 3 | C49: 0.03 | D49: 0.03 | E49: 0.03 | F49: =INDEX(C49:E49,$D$3) -> 0.03
A50: Participación pago cuenta a cuenta / prepago en Flow | B50: Año 1 | C50: 0.1 | D50: 0.1 | E50: 0.1 | F50: =INDEX(C50:E50,$D$3) -> 0.1 | G50: Supuesto
A51: Participación pago cuenta a cuenta / prepago en Flow | B51: Año 2 | C51: 0.25 | D51: 0.25 | E51: 0.25 | F51: =INDEX(C51:E51,$D$3) -> 0.25
A52: Participación pago cuenta a cuenta / prepago en Flow | B52: Año 3 | C52: 0.35 | D52: 0.35 | E52: 0.35 | F52: =INDEX(C52:E52,$D$3) -> 0.35
A53: Realización del ahorro de islero | B53: Año 1 | C53: 0 | D53: 0 | E53: 0 | F53: =INDEX(C53:E53,$D$3) -> 0 | G53: Supuesto: 0 % en fase 1 (rol se redefine); luego rotación natural y tienda
A54: Realización del ahorro de islero | B54: Año 2 | C54: 0.35 | D54: 0.35 | E54: 0.35 | F54: =INDEX(C54:E54,$D$3) -> 0.35
A55: Realización del ahorro de islero | B55: Año 3 | C55: 0.7 | D55: 0.7 | E55: 0.7 | F55: =INDEX(C55:E55,$D$3) -> 0.7
A56: Tasa de disputas Flow | B56: Año 1 | C56: 0.0045 | D56: 0.0045 | E56: 0.0045 | F56: =INDEX(C56:E56,$D$3) -> 0.0045 | G56: Supuesto: plan anti-disputas (M5). Piloto sem. 8: 0,61 %
...

Sheet Controles
A1: Controles de conciliación
A2: Plan directivo (420 estaciones × 6 islas). Una sola fuente para las cifras de CAPEX que aparecen en los documentos.
A4: Concepto | B4: Fórmula | C4: USD
A5: Kits de isla | B5: 420 × 6 × kit | C5: =420*6*Supuestos!$C$14 -> 17136000
A6: POS legado | B6: 360 × integración legado | C6: =360*Supuestos!$C$16 -> 3420000
A7: POS cloud | B7: 60 × integración cloud | C7: =60*Supuestos!$C$17 -> 120000
A8: CAPEX base red completa | B8: kits + POS | C8: =C5+C6+C7 -> 20676000
A9: Instalación y contingencia | B9: % sobre kits | C9: =C5*Supuestos!$C$15 -> 1713600
A10: Red completa instalada | B10: base + instalación | C10: =C8+C9 -> 22389600
A11: Piloto existente (3 estaciones) | B11: 3 × 6 kits instalados + 3 POS legado | C11: =3*6*Supuestos!$C$14*(1+Supuestos!$C$15)+3*Supuestos!$C$16 -> 163140
A12: CAPEX incremental 3 → 420 | B12: red instalada − piloto | C12: =C10-C11 -> 22226460
A13: Presupuesto aprobado | B13: dato del caso | C13: 4200000
A14: Múltiplo del presupuesto | B14: incremental / presupuesto | C14: =C12/C13 -> 5.2920143
A16: Recuperación (escenario seleccionado)
A17: Indicador | B17: Cómo leerlo | C17: Valor
A18: VPN a 3 años | B18: Flujos descontados al 12 % | C18: =Modelo!C38 -> -5642455.4
A19: VPN a 5 años | B19: Años 4–5 en régimen, sin CAPEX nuevo | C19: =Modelo!C39 -> -3674462.5
A20: Flujo acumulado al año 5 | B20: Sin descontar | C20: =Modelo!G34 -> -3318433.2
A21: Recuperación del programa | B21: Primer año con acumulado ≥ 0 | C21: =Modelo!C40 -> Después del año 5
A22: Indicador unitario (años) | B22: CAPEX de una estación / su contribución ANTES de costos fijos. No es el payback del programa. | C22: =Modelo!C47 -> 2.1188649

Sheet Modelo
A1: Caso de negocio Flow · escenario seleccionado
A2: ="Escenario: "&Supuestos!C3 -> Escenario: C
A4: Concepto | B4: Unidad | C4: Año 1 | D4: Año 2 | E4: Año 3 | F4: Año 4 (run-rate) | G4: Año 5 (run-rate) | H4: Nota
A5: Estaciones al inicio | B5: est. | C5: =Supuestos!$F$31 -> 3 | D5: =C6 -> 120 | E5: =D6 -> 200 | F5: =E6 -> 250 | G5: =F6 -> 250
A6: Estaciones al cierre | B6: est. | C6: =Supuestos!$F$35 -> 120 | D6: =Supuestos!$F$36 -> 200 | E6: =Supuestos!$F$37 -> 250 | F6: =E6 -> 250 | G6: =F6 -> 250 | H6: Años 4–5 sin nuevas estaciones
A7: Estaciones nuevas | B7: est. | C7: =C6-C5 -> 117 | D7: =D6-D5 -> 80 | E7: =E6-E5 -> 50 | F7: =F6-F5 -> 0 | G7: =G6-G5 -> 0
A8: de ellas con POS cloud | B8: est. | C8: =MIN(C7,Supuestos!$F$38) -> 60 | D8: =MIN(D7,Supuestos!$F$39) -> 0 | E8: =MIN(E7,Supuestos!$F$40) -> 0 | F8: =0 -> 0 | G8: =0 -> 0
A9: Estaciones activas (promedio) | B9: est. | C9: =(C5+C6)/2 -> 61.5 | D9: =(D5+D6)/2 -> 160 | E9: =(E5+E6)/2 -> 225 | F9: =(F5+F6)/2 -> 250 | G9: =(G5+G6)/2 -> 250 | H9: Convención de medio año
A10: Vehículos atendidos | B10: veh | C10: =C9*Supuestos!$F$10*Supuestos!$F$11*Supuestos!$F$12 -> 9899347.5 | D10: =D9*Supuestos!$F$10*Supuestos!$F$11*Supuestos!$F$12 -> 25754400 | E10: =E9*Supuestos!$F$10*Supuestos!$F$11*Supuestos!$F$12 -> 36217125 | F10: =F9*Supuestos!$F$10*Supuestos!$F$11*Supuestos!$F$12 -> 40241250 | G10: =G9*Supuestos!$F$10*Supuestos!$F$11*Supuestos!$F$12 -> 40241250
A11: Transacciones Flow sin intervención | B11: txn | C11: =C10*Supuestos!$F$41*Supuestos!$F$44 -> 1385908.6 | D11: =D10*Supuestos!$F$42*Supuestos!$F$45 -> 5872003.2 | E11: =E10*Supuestos!$F$43*Supuestos!$F$46 -> 11589480 | F11: =F10*Supuestos!$F$43*Supuestos!$F$46 -> 12877200 | G11: =G10*Supuestos!$F$43*Supuestos!$F$46 -> 12877200 | H11: Base × enrolamiento × automatización
A12: Ticket promedio | B12: USD | C12: =Supuestos!$F$7/Supuestos!$F$6 -> 29.5 | D12: =Supuestos!$F$7/Supuestos!$F$6 -> 29.5 | E12: =Supuestos!$F$7/Supuestos!$F$6 -> 29.5 | F12: =Supuestos!$F$7/Supuestos!$F$6 -> 29.5 | G12: =Supuestos!$F$7/Supuestos!$F$6 -> 29.5
A13: Margen bruto por transacción | B13: USD | C13: =Supuestos!$F$7/Supuestos!$F$8*Supuestos!$F$9 -> 1.54875 | D13: =Supuestos!$F$7/Supuestos!$F$8*Supuestos!$F$9 -> 1.54875 | E13: =Supuestos!$F$7/Supuestos!$F$8*Supuestos!$F$9 -> 1.54875 | F13: =Supuestos!$F$7/Supuestos!$F$8*Supuestos!$F$9 -> 1.54875 | G13: =Supuestos!$F$7/Supuestos!$F$8*Supuestos!$F$9 -> 1.54875 | H13: galones × margen/galón
A14: BENEFICIOS
A15: Margen de volumen incremental | B15: USD | C15: =C10*Supuestos!$F$47*C13 -> 153316.14 | D15: =D10*Supuestos!$F$48*D13 -> 797742.54 | E15: =E10*Supuestos!$F$49*E13 -> 1682738.2 | F15: =F10*Supuestos!$F$49*F13 -> 1869709.1 | G15: =G10*Supuestos!$F$49*G13 -> 1869709.1 | H15: Throughput + lealtad
A16: Ahorro en costo de medios de pago | B16: USD | C16: =C11*C12*(((1-Supuestos!$F$22)*Supuestos!$F$19+Supuestos!$F$22*Supuestos!$F$21)-((1-Supuestos!$F$50)*Supuestos!$F$19+Supuestos!$F$50*Supuestos!$F$20)) -> -20442.153 | D16: =D11*D12*(((1-Supuestos!$F$22)*Supuestos!$F$19+Supuestos!$F$22*Supuestos!$F$21)-((1-Supuestos!$F$51)*Supuestos!$F$19+Supuestos!$F$51*Supuestos!$F$20)) -> 251174.94 | E16: =E11*E12*(((1-Supuestos!$F$22)*Supuestos!$F$19+Supuestos!$F$22*Supuestos!$F$21)-((1-Supuestos!$F$52)*Supuestos!$F$19+Supuestos!$F$52*Supuestos!$F$20)) -> 940196.56 | F16: =F11*F12*(((1-Supuestos!$F$22)*Supuestos!$F$19+Supuestos!$F$22*Supuestos!$F$21)-((1-Supuestos!$F$52)*Supuestos!$F$19+Supuestos!$F$52*Supuestos!$F$20)) -> 1044662.8 | G16: =G11*G12*(((1-Supuestos!$F$22)*Supuestos!$F$19+Supuestos!$F$22*Supuestos!$F$21)-((1-Supuestos!$F$52)*Supuestos!$F$19+Supuestos!$F$52*Supuestos!$F$20)) -> 1044662.8 | H16: Negativo si el efectivo migra a tarjeta
A17: Capacidad de islero monetizada | B17: USD | C17: =C11*Supuestos!$F$23/60*Supuestos!$F$24*Supuestos!$F$53 -> 0 | D17: =D11*Supuestos!$F$23/60*Supuestos!$F$24*Supuestos!$F$54 -> 369936.2 | E17: =E11*Supuestos!$F$23/60*Supuestos!$F$24*Supuestos!$F$55 -> 1460274.5 | F17: =F11*Supuestos!$F$23/60*Supuestos!$F$24*Supuestos!$F$55 -> 1622527.2 | G17: =G11*Supuestos!$F$23/60*Supuestos!$F$24*Supuestos!$F$55 -> 1622527.2 | H17: Sin despidos en fase 1
A18: Total beneficios | B18: USD | C18: =C15+C16+C17 -> 132873.99 | D18: =D15+D16+D17 -> 1418853.7 | E18: =E15+E16+E17 -> 4083209.2 | F18: =F15+F16+F17 -> 4536899.1 | G18: =G15+G16+G17 -> 4536899.1
A19: COSTOS OPERATIVOS
A20: OPEX de islas | B20: USD | C20: =C9*Supuestos!$F$13*Supuestos!$F$18*12 -> 125460 | D20: =D9*Supuestos!$F$13*Supuestos!$F$18*12 -> 326400 | E20: =E9*Supuestos!$F$13*Supuestos!$F$18*12 -> 459000 | F20: =F9*Supuestos!$F$13*Supuestos!$F$18*12 -> 510000 | G20: =G9*Supuestos!$F$13*Supuestos!$F$18*12 -> 510000
A21: PSP / tokenización | B21: USD | C21: =C11*Supuestos!$F$25 -> 27718.173 | D21: =D11*Supuestos!$F$25 -> 117440.06 | E21: =E11*Supuestos!$F$25 -> 231789.6 | F21: =F11*Supuestos!$F$25 -> 257544 | G21: =G11*Supuestos!$F$25 -> 257544
A22: Disputas y contracargos | B22: USD | C22: =C11*Supuestos!$F$56*(Supuestos!$F$26*C12+Supuestos!$F$27) -> 167140.58 | D22: =D11*Supuestos!$F$57*(Supuestos!$F$26*D12+Supuestos!$F$27) -> 472109.06 | E22: =E11*Supuestos!$F$58*(Supuestos!$F$26*E12+Supuestos!$F$27) -> 776495.16 | F22: =F11*Supuestos!$F$58*(Supuestos!$F$26*F12+Supuestos!$F$27) -> 862772.4 | G22: =G11*Supuestos!$F$58*(Supuestos!$F$26*G12+Supuestos!$F$27) -> 862772.4
A23: Agente de soporte con LLM | B23: USD | C23: =C11*Supuestos!$F$28*Supuestos!$F$29 -> 2217.4538 | D23: =D11*Supuestos!$F$28*Supuestos!$F$29 -> 9395.2051 | E23: =E11*Supuestos!$F$28*Supuestos!$F$29 -> 18543.168 | F23: =F11*Supuestos!$F$28*Supuestos!$F$29 -> 20603.52 | G23: =G11*Supuestos!$F$28*Supuestos!$F$29 -> 20603.52
A24: Equipo y plataforma | B24: USD | C24: =Supuestos!$F$59 -> 1100000 | D24: =Supuestos!$F$60 -> 1000000 | E24: =Supuestos!$F$61 -> 1000000 | F24: =Supuestos!$F$61 -> 1000000 | G24: =Supuestos!$F$61 -> 1000000
A25: Enrolamiento y marketing | B25: USD | C25: =Supuestos!$F$62 -> 250000 | D25: =Supuestos!$F$63 -> 300000 | E25: =Supuestos!$F$64 -> 250000 | F25: =Supuestos!$F$64 -> 250000 | G25: =Supuestos!$F$64 -> 250000
A26: Total costos operativos | B26: USD | C26: =SUM(C20:C25) -> 1672536.2 | D26: =SUM(D20:D25) -> 2225344.3 | E26: =SUM(E20:E25) -> 2735827.9 | F26: =SUM(F20:F25) -> 2900919.9 | G26: =SUM(G20:G25) -> 2900919.9
A27: EBITDA del programa | B27: USD | C27: =C18-C26 -> -1539662.2 | D27: =D18-D26 -> -806490.65 | E27: =E18-E26 -> 1347381.3 | F27: =F18-F26 -> 1635979.2 | G27: =G18-G26 -> 1635979.2
A28: INVERSIÓN
A29: Kits de isla e instalación | B29: USD | C29: =C7*Supuestos!$F$13*Supuestos!$F$14*(1+Supuestos!$F$15) -> 1750320 | D29: =D7*Supuestos!$F$13*Supuestos!$F$14*(1+Supuestos!$F$15) -> 1196800 | E29: =E7*Supuestos!$F$13*Supuestos!$F$14*(1+Supuestos!$F$15) -> 748000 | F29: =F7*Supuestos!$F$13*Supuestos!$F$14*(1+Supuestos!$F$15) -> 0 | G29: =G7*Supuestos!$F$13*Supuestos!$F$14*(1+Supuestos!$F$15) -> 0
A30: Integración POS | B30: USD | C30: =C8*Supuestos!$F$17+(C7-C8)*Supuestos!$F$16 -> 661500 | D30: =D8*Supuestos!$F$17+(D7-D8)*Supuestos!$F$16 -> 760000 | E30: =E8*Supuestos!$F$17+(E7-E8)*Supuestos!$F$16 -> 475000 | F30: =F8*Supuestos!$F$17+(F7-F8)*Supuestos!$F$16 -> 0 | G30: =G8*Supuestos!$F$17+(G7-G8)*Supuestos!$F$16 -> 0
A31: Total CAPEX | B31: USD | C31: =C29+C30 -> 2411820 | D31: =D29+D30 -> 1956800 | E31: =E29+E30 -> 1223000 | F31: =F29+F30 -> 0 | G31: =G29+G30 -> 0
A32: FLUJO
A33: Flujo de caja libre | B33: USD | C33: =C27-C31 -> -3951482.2 | D33: =D27-D31 -> -2763290.6 | E33: =E27-E31 -> 124381.29 | F33: =F27-F31 -> 1635979.2 | G33: =G27-G31 -> 1635979.2
A34: Flujo acumulado | B34: USD | C34: =C33 -> -3951482.2 | D34: =C34+D33 -> -6714772.9 | E34: =D34+E33 -> -6590391.6 | F34: =E34+F33 -> -4954412.4 | G34: =F34+G33 -> -3318433.2
A35: Uso de caja del año (CAPEX + OPEX − beneficios) | B35: USD | C35: =-C33 -> 3951482.2 | D35: =-D33 -> 2763290.6 | E35: =-E33 -> -124381.29 | F35: =-F33 -> -1635979.2 | G35: =-G33 -> -1635979.2 | H35: Comparar Año 1 con el presupuesto de USD 4,2 M
A37: Indicadores
A38: VPN a 3 años | C38: =NPV(Supuestos!$F$30,C33:E33) -> -5642455.4
A39: VPN a 5 años (años 4–5 en run-rate) | C39: =NPV(Supuestos!$F$30,C33:G33) -> -3674462.5
A40: Recuperación del programa (flujo acumulado ≥ 0) | C40: =IF(COUNTIF(C34:G34,"<0")=5,"Después del año 5","Año "&(COUNTIF(C34:G34,"<0")+1)) -> Después del año 5
A41: CAPEX total años 1–3 | C41: =SUM(C31:E31) -> 5591620
A42: Flujo acumulado al cierre del año 5 | C42: =G34 -> -3318433.2
...

Sheet Sensibilidad
A1: Sensibilidad del VPN a 5 años · escenario seleccionado
A2: Cada fila multiplica un grupo de supuestos (azul). La fila 'Base' debe igualar Modelo (control en la columna D).
A4: Caso | B4: VPN 5 años | C4: Δ vs base | D4: Control | E4: Tráfico | F4: Volumen incr. | G4: Enrolamiento | H4: Automatización | I4: Costo kit | J4: Tasa disputas | K4: Costos fijos | L4: Realización islero | M4: Margen/galón | N4: Mix cuenta a cuenta | O4: A1 Veh | P4: A1 Txn Flow | Q4: A1 Beneficios | R4: A1 OPEX | S4: A1 CAPEX | T4: A1 FCF | U4: A2 Veh | V4: A2 Txn Flow | W4: A2 Beneficios | X4: A2 OPEX | Y4: A2 CAPEX | Z4: A2 FCF | AA4: A3 Veh | AB4: A3 Txn Flow | AC4: A3 Beneficios | AD4: A3 OPEX | AE4: A3 CAPEX | AF4: A3 FCF | AG4: A4 Veh | AH4: A4 Txn Flow | AI4: A4 Beneficios | AJ4: A4 OPEX | AK4: A4 CAPEX | AL4: A4 FCF | AM4: A5 Veh | AN4: A5 Txn Flow | AO4: A5 Beneficios | AP4: A5 OPEX | AQ4: A5 CAPEX | AR4: A5 FCF
A5: Base | B5: =NPV(Supuestos!$F$30,T5,Z5,AF5,AL5,AR5) -> -3674462.5 | C5: =B5-$B$5 -> 0 | D5: =IF(ABS(B5-Modelo!C39)<1,"OK = Modelo","REVISAR") -> OK = Modelo | E5: 1 | F5: 1 | G5: 1 | H5: 1 | I5: 1 | J5: 1 | K5: 1 | L5: 1 | M5: 1 | N5: 1 | O5: =((Supuestos!$F$31)+(Supuestos!$F$35))/2*Supuestos!$F$10*Supuestos!$F$11*Supuestos!$F$12*$E5 -> 9899347.5 | P5: =O5*MIN(1,Supuestos!$F$41*$G5)*MIN(1,Supuestos!$F$44*$H5) -> 1385908.6 | Q5: =O5*Supuestos!$F$47*$F5*(Supuestos!$F$7/Supuestos!$F$8*Supuestos!$F$9*$M5)+P5*(Supuestos!$F$7/Supuestos!$F$6)*(((1-Supuestos!$F$22)*Supuestos!$F$19+Supuestos!$F$22*Supuestos!$F$21)-((1-MIN(1,Supuestos!$F$50*$N5))*Supuestos!$F$19+MIN(1,Supuestos!$F$50*$N5)*Supuestos!$F$20))+P5*Supuestos!$F$23/60*Supuestos!$F$24*MIN(1,Supuestos!$F$53*$L5) -> 132873.99 | R5: =((Supuestos!$F$31)+(Supuestos!$F$35))/2*Supuestos!$F$13*Supuestos!$F$18*12+P5*Supuestos!$F$25+P5*Supuestos!$F$56*$J5*(Supuestos!$F$26*(Supuestos!$F$7/Supuestos!$F$6)+Supuestos!$F$27)+P5*Supuestos!$F$28*Supuestos!$F$29+(Supuestos!$F$59+Supuestos!$F$62)*$K5 -> 1672536.2 | S5: =(Supuestos!$F$35-Supuestos!$F$31)*Supuestos!$F$13*Supuestos!$F$14*$I5*(1+Supuestos!$F$15)+MIN(Supuestos!$F$35-Supuestos!$F$31,Supuestos!$F$38)*Supuestos!$F$17+((Supuestos!$F$35-Supuestos!$F$31)-MIN(Supuestos!$F$35-Supuestos!$F$31,Supuestos!$F$38))*Supuestos!$F$16 -> 2411820 | T5: =Q5-R5-S5 -> -3951482.2 | U5: =((Supuestos!$F$35)+(Supuestos!$F$36))/2*Supuestos!$F$10*Supuestos!$F$11*Supuestos!$F$12*$E5 -> 25754400 | V5: =U5*MIN(1,Supuestos!$F$42*$G5)*MIN(1,Supuestos!$F$45*$H5) -> 5872003.2 | W5: =U5*Supuestos!$F$48*$F5*(Supuestos!$F$7/Supuestos!$F$8*Supuestos!$F$9*$M5)+V5*(Supuestos!$F$7/Supuestos!$F$6)*(((1-Supuestos!$F$22)*Supuestos!$F$19+Supuestos!$F$22*Supuestos!$F$21)-((1-MIN(1,Supuestos!$F$51*$N5))*Supuestos!$F$19+MIN(1,Supuestos!$F$51*$N5)*Supuestos!$F$20))+V5*Supuestos!$F$23/60*Supuestos!$F$24*MIN(1,Supuestos!$F$54*$L5) -> 1418853.7 | X5: =((Supuestos!$F$35)+(Supuestos!$F$36))/2*Supuestos!$F$13*Supuestos!$F$18*12+V5*Supuestos!$F$25+V5*Supuestos!$F$57*$J5*(Supuestos!$F$26*(Supuestos!$F$7/Supuestos!$F$6)+Supuestos!$F$27)+V5*Supuestos!$F$28*Supuestos!$F$29+(Supuestos!$F$60+Supuestos!$F$63)*$K5 -> 2225344.3 | Y5: =(Supuestos!$F$36-Supuestos!$F$35)*Supuestos!$F$13*Supuestos!$F$14*$I5*(1+Supuestos!$F$15)+MIN(Supuestos!$F$36-Supuestos!$F$35,Supuestos!$F$39)*Supuestos!$F$17+((Supuestos!$F$36-Supuestos!$F$35)-MIN(Supuestos!$F$36-Supuestos!$F$35,Supuestos!$F$39))*Supuestos!$F$16 -> 1956800 | Z5: =W5-X5-Y5 -> -2763290.6 | AA5: =((Supuestos!$F$36)+(Supuestos!$F$37))/2*Supuestos!$F$10*Supuestos!$F$11*Supuestos!$F$12*$E5 -> 36217125 | AB5: =AA5*MIN(1,Supuestos!$F$43*$G5)*MIN(1,Supuestos!$F$46*$H5) -> 11589480 | AC5: =AA5*Supuestos!$F$49*$F5*(Supuestos!$F$7/Supuestos!$F$8*Supuestos!$F$9*$M5)+AB5*(Supuestos!$F$7/Supuestos!$F$6)*(((1-Supuestos!$F$22)*Supuestos!$F$19+Supuestos!$F$22*Supuestos!$F$21)-((1-MIN(1,Supuestos!$F$52*$N5))*Supuestos!$F$19+MIN(1,Supuestos!$F$52*$N5)*Supuestos!$F$20))+AB5*Supuestos!$F$23/60*Supuestos!$F$24*MIN(1,Supuestos!$F$55*$L5) -> 4083209.2 | AD5: =((Supuestos!$F$36)+(Supuestos!$F$37))/2*Supuestos!$F$13*Supuestos!$F$18*12+AB5*Supuestos!$F$25+AB5*Supuestos!$F$58*$J5*(Supuestos!$F$26*(Supuestos!$F$7/Supuestos!$F$6)+Supuestos!$F$27)+AB5*Supuestos!$F$28*Supuestos!$F$29+(Supuestos!$F$61+Supuestos!$F$64)*$K5 -> 2735827.9 | AE5: =(Supuestos!$F$37-Supuestos!$F$36)*Supuestos!$F$13*Supuestos!$F$14*$I5*(1+Supuestos!$F$15)+MIN(Supuestos!$F$37-Supuestos!$F$36,Supuestos!$F$40)*Supuestos!$F$17+((Supuestos!$F$37-Supuestos!$F$36)-MIN(Supuestos!$F$37-Supuestos!$F$36,Supuestos!$F$40))*Supuestos!$F$16 -> 1223000 | AF5: =AC5-AD5-AE5 -> 124381.29 | AG5: =((Supuestos!$F$37)+(Supuestos!$F$37))/2*Supuestos!$F$10*Supuestos!$F$11*Supuestos!$F$12*$E5 -> 40241250 | AH5: =AG5*MIN(1,Supuestos!$F$43*$G5)*MIN(1,Supuestos!$F$46*$H5) -> 12877200 | AI5: =AG5*Supuestos!$F$49*$F5*(Supuestos!$F$7/Supuestos!$F$8*Supuestos!$F$9*$M5)+AH5*(Supuestos!$F$7/Supuestos!$F$6)*(((1-Supuestos!$F$22)*Supuestos!$F$19+Supuestos!$F$22*Supuestos!$F$21)-((1-MIN(1,Supuestos!$F$52*$N5))*Supuestos!$F$19+MIN(1,Supuestos!$F$52*$N5)*Supuestos!$F$20))+AH5*Supuestos!$F$23/60*Supuestos!$F$24*MIN(1,Supuestos!$F$55*$L5) -> 4536899.1 | AJ5: =((Supuestos!$F$37)+(Supuestos!$F$37))/2*Supuestos!$F$13*Supuestos!$F$18*12+AH5*Supuestos!$F$25+AH5*Supuestos!$F$58*$J5*(Supuestos!$F$26*(Supuestos!$F$7/Supuestos!$F$6)+Supuestos!$F$27)+AH5*Supuestos!$F$28*Supuestos!$F$29+(Supuestos!$F$61+Supuestos!$F$64)*$K5 -> 2900919.9 | AK5: =0 -> 0 | AL5: =AI5-AJ5-AK5 -> 1635979.2 | AM5: =((Supuestos!$F$37)+(Supuestos!$F$37))/2*Supuestos!$F$10*Supuestos!$F$11*Supuestos!$F$12*$E5 -> 40241250 | AN5: =AM5*MIN(1,Supuestos!$F$43*$G5)*MIN(1,Supuestos!$F$46*$H5) -> 12877200 | AO5: =AM5*Supuestos!$F$49*$F5*(Supuestos!$F$7/Supuestos!$F$8*Supuestos!$F$9*$M5)+AN5*(Supuestos!$F$7/Supuestos!$F$6)*(((1-Supuestos!$F$22)*Supuestos!$F$19+Supuestos!$F$22*Supuestos!$F$21)-((1-MIN(1,Supuestos!$F$52*$N5))*Supuestos!$F$19+MIN(1,Supuestos!$F$52*$N5)*Supuestos!$F$20))+AN5*Supuestos!$F$23/60*Supuestos!$F$24*MIN(1,Supuestos!$F$55*$L5) -> 4536899.1 | AP5: =((Supuestos!$F$37)+(Supuestos!$F$37))/2*Supuestos!$F$13*Supuestos!$F$18*12+AN5*Supuestos!$F$25+AN5*Supuestos!$F$58*$J5*(Supuestos!$F$26*(Supuestos!$F$7/Supuestos!$F$6)+Supuestos!$F$27)+AN5*Supuestos!$F$28*Supuestos!$F$29+(Supuestos!$F$61+Supuestos!$F$64)*$K5 -> 2900919.9 | AQ5: =0 -> 0 | AR5: =AO5-AP5-AQ5 -> 1635979.2
A6: Tráfico −25 % | B6: =NPV(Supuestos!$F$30,T6,Z6,AF6,AL6,AR6) -> -5388700.2 | C6: =B6-$B$5 -> -1714237.8 | E6: 0.75 | F6: 1 | G6: 1 | H6: 1 | I6: 1 | J6: 1 | K6: 1 | L6: 1 | M6: 1 | N6: 1 | O6: =((Supuestos!$F$31)+(Supuestos!$F$35))/2*Supuestos!$F$10*Supuestos!$F$11*Supuestos!$F$12*$E6 -> 7424510.6 | P6: =O6*MIN(1,Supuestos!$F$41*$G6)*MIN(1,Supuestos!$F$44*$H6) -> 1039431.5 | Q6: =O6*Supuestos!$F$47*$F6*(Supuestos!$F$7/Supuestos!$F$8*Supuestos!$F$9*$M6)+P6*(Supuestos!$F$7/Supuestos!$F$6)*(((1-Supuestos!$F$22)*Supuestos!$F$19+Supuestos!$F$22*Supuestos!$F$21)-((1-MIN(1,Supuestos!$F$50*$N6))*Supuestos!$F$19+MIN(1,Supuestos!$F$50*$N6)*Supuestos!$F$20))+P6*Supuestos!$F$23/60*Supuestos!$F$24*MIN(1,Supuestos!$F$53*$L6) -> 99655.494 | R6: =((Supuestos!$F$31)+(Supuestos!$F$35))/2*Supuestos!$F$13*Supuestos!$F$18*12+P6*Supuestos!$F$25+P6*Supuestos!$F$56*$J6*(Supuestos!$F$26*(Supuestos!$F$7/Supuestos!$F$6)+Supuestos!$F$27)+P6*Supuestos!$F$28*Supuestos!$F$29+(Supuestos!$F$59+Supuestos!$F$62)*$K6 -> 1623267.2 | S6: =(Supuestos!$F$35-Supuestos!$F$31)*Supuestos!$F$13*Supuestos!$F$14*$I6*(1+Supuestos!$F$15)+MIN(Supuestos!$F$35-Supuestos!$F$31,Supuestos!$F$38)*Supuestos!$F$17+((Supuestos!$F$35-Supuestos!$F$31)-MIN(Supuestos!$F$35-Supuestos!$F$31,Supuestos!$F$38))*Supuestos!$F$16 -> 2411820 | T6: =Q6-R6-S6 -> -3935431.7 | U6: =((Supuestos!$F$35)+(Supuestos!$F$36))/2*Supuestos!$F$10*Supuestos!$F$11*Supuestos!$F$12*$E6 -> 19315800 | V6: =U6*MIN(1,Supuestos!$F$42*$G6)*MIN(1,Supuestos!$F$45*$H6) -> 4404002.4 | W6: =U6*Supuestos!$F$48*$F6*(Supuestos!$F$7/Supuestos!$F$8*Supuestos!$F$9*$M6)+V6*(Supuestos!$F$7/Supuestos!$F$6)*(((1-Supuestos!$F$22)*Supuestos!$F$19+Supuestos!$F$22*Supuestos!$F$21)-((1-MIN(1,Supuestos!$F$51*$N6))*Supuestos!$F$19+MIN(1,Supuestos!$F$51*$N6)*Supuestos!$F$20))+V6*Supuestos!$F$23/60*Supuestos!$F$24*MIN(1,Supuestos!$F$54*$L6) -> 1064140.3 | X6: =((Supuestos!$F$35)+(Supuestos!$F$36))/2*Supuestos!$F$13*Supuestos!$F$18*12+V6*Supuestos!$F$25+V6*Supuestos!$F$57*$J6*(Supuestos!$F$26*(Supuestos!$F$7/Supuestos!$F$6)+Supuestos!$F$27)+V6*Supuestos!$F$28*Supuestos!$F$29+(Supuestos!$F$60+Supuestos!$F$63)*$K6 -> 2075608.2 | Y6: =(Supuestos!$F$36-Supuestos!$F$35)*Supuestos!$F$13*Supuestos!$F$14*$I6*(1+Supuestos!$F$15)+MIN(Supuestos!$F$36-Supuestos!$F$35,Supuestos!$F$39)*Supuestos!$F$17+((Supuestos!$F$36-Supuestos!$F$35)-MIN(Supuestos!$F$36-Supuestos!$F$35,Supuestos!$F$39))*Supuestos!$F$16 -> 1956800 | Z6: =W6-X6-Y6 -> -2968268 | AA6: =((Supuestos!$F$36)+(Supuestos!$F$37))/2*Supuestos!$F$10*Supuestos!$F$11*Supuestos!$F$12*$E6 -> 27162844 | AB6: =AA6*MIN(1,Supuestos!$F$43*$G6)*MIN(1,Supuestos!$F$46*$H6) -> 8692110 | AC6: =AA6*Supuestos!$F$49*$F6*(Supuestos!$F$7/Supuestos!$F$8*Supuestos!$F$9*$M6)+AB6*(Supuestos!$F$7/Supuestos!$F$6)*(((1-Supuestos!$F$22)*Supuestos!$F$19+Supuestos!$F$22*Supuestos!$F$21)-((1-MIN(1,Supuestos!$F$52*$N6))*Supuestos!$F$19+MIN(1,Supuestos!$F$52*$N6)*Supuestos!$F$20))+AB6*Supuestos!$F$23/60*Supuestos!$F$24*MIN(1,Supuestos!$F$55*$L6) -> 3062406.9 | AD6: =((Supuestos!$F$36)+(Supuestos!$F$37))/2*Supuestos!$F$13*Supuestos!$F$18*12+AB6*Supuestos!$F$25+AB6*Supuestos!$F$58*$J6*(Supuestos!$F$26*(Supuestos!$F$7/Supuestos!$F$6)+Supuestos!$F$27)+AB6*Supuestos!$F$28*Supuestos!$F$29+(Supuestos!$F$61+Supuestos!$F$64)*$K6 -> 2479120.9 | AE6: =(Supuestos!$F$37-Supuestos!$F$36)*Supuestos!$F$13*Supuestos!$F$14*$I6*(1+Supuestos!$F$15)+MIN(Supuestos!$F$37-Supuestos!$F$36,Supuestos!$F$40)*Supuestos!$F$17+((Supuestos!$F$37-Supuestos!$F$36)-MIN(Supuestos!$F$37-Supuestos!$F$36,Supuestos!$F$40))*Supuestos!$F$16 -> 1223000 | AF6: =AC6-AD6-AE6 -> -639714.03 | AG6: =((Supuestos!$F$37)+(Supuestos!$F$37))/2*Supuestos!$F$10*Supuestos!$F$11*Supuestos!$F$12*$E6 -> 30180938 | AH6: =AG6*MIN(1,Supuestos!$F$43*$G6)*MIN(1,Supuestos!$F$46*$H6) -> 9657900 | AI6: =AG6*Supuestos!$F$49*$F6*(Supuestos!$F$7/Supuestos!$F$8*Supuestos!$F$9*$M6)+AH6*(Supuestos!$F$7/Supuestos!$F$6)*(((1-Supuestos!$F$22)*Supuestos!$F$19+Supuestos!$F$22*Supuestos!$F$21)-((1-MIN(1,Supuestos!$F$52*$N6))*Supuestos!$F$19+MIN(1,Supuestos!$F$52*$N6)*Supuestos!$F$20))+AH6*Supuestos!$F$23/60*Supuestos!$F$24*MIN(1,Supuestos!$F$55*$L6) -> 3402674.3 | AJ6: =((Supuestos!$F$37)+(Supuestos!$F$37))/2*Supuestos!$F$13*Supuestos!$F$18*12+AH6*Supuestos!$F$25+AH6*Supuestos!$F$58*$J6*(Supuestos!$F$26*(Supuestos!$F$7/Supuestos!$F$6)+Supuestos!$F$27)+AH6*Supuestos!$F$28*Supuestos!$F$29+(Supuestos!$F$61+Supuestos!$F$64)*$K6 -> 2615689.9 | AK6: =0 -> 0 | AL6: =AI6-AJ6-AK6 -> 786984.41 | AM6: =((Supuestos!$F$37)+(Supuestos!$F$37))/2*Supuestos!$F$10*Supuestos!$F$11*Supuestos!$F$12*$E6 -> 30180938 | AN6: =AM6*MIN(1,Supuestos!$F$43*$G6)*MIN(1,Supuestos!$F$46*$H6) -> 9657900 | AO6: =AM6*Supuestos!$F$49*$F6*(Supuestos!$F$7/Supuestos!$F$8*Supuestos!$F$9*$M6)+AN6*(Supuestos!$F$7/Supuestos!$F$6)*(((1-Supuestos!$F$22)*Supuestos!$F$19+Supuestos!$F$22*Supuestos!$F$21)-((1-MIN(1,Supuestos!$F$52*$N6))*Supuestos!$F$19+MIN(1,Supuestos!$F$52*$N6)*Supuestos!$F$20))+AN6*Supuestos!$F$23/60*Supuestos!$F$24*MIN(1,Supuestos!$F$55*$L6) -> 3402674.3 | AP6: =((Supuestos!$F$37)+(Supuestos!$F$37))/2*Supuestos!$F$13*Supuestos!$F$18*12+AN6*Supuestos!$F$25+AN6*Supuestos!$F$58*$J6*(Supuestos!$F$26*(Supuestos!$F$7/Supuestos!$F$6)+Supuestos!$F$27)+AN6*Supuestos!$F$28*Supuestos!$F$29+(Supuestos!$F$61+Supuestos!$F$64)*$K6 -> 2615689.9 | AQ6: =0 -> 0 | AR6: =AO6-AP6-AQ6 -> 786984.41
A7: Tráfico +25 % | B7: =NPV(Supuestos!$F$30,T7,Z7,AF7,AL7,AR7) -> -1960224.7 | C7: =B7-$B$5 -> 1714237.8 | E7: 1.25 | F7: 1 | G7: 1 | H7: 1 | I7: 1 | J7: 1 | K7: 1 | L7: 1 | M7: 1 | N7: 1 | O7: =((Supuestos!$F$31)+(Supuestos!$F$35))/2*Supuestos!$F$10*Supuestos!$F$11*Supuestos!$F$12*$E7 -> 12374184 | P7: =O7*MIN(1,Supuestos!$F$41*$G7)*MIN(1,Supuestos!$F$44*$H7) -> 1732385.8 | Q7: =O7*Supuestos!$F$47*$F7*(Supuestos!$F$7/Supuestos!$F$8*Supuestos!$F$9*$M7)+P7*(Supuestos!$F$7/Supuestos!$F$6)*(((1-Supuestos!$F$22)*Supuestos!$F$19+Supuestos!$F$22*Supuestos!$F$21)-((1-MIN(1,Supuestos!$F$50*$N7))*Supuestos!$F$19+MIN(1,Supuestos!$F$50*$N7)*Supuestos!$F$20))+P7*Supuestos!$F$23/60*Supuestos!$F$24*MIN(1,Supuestos!$F$53*$L7) -> 166092.49 | R7: =((Supuestos!$F$31)+(Supuestos!$F$35))/2*Supuestos!$F$13*Supuestos!$F$18*12+P7*Supuestos!$F$25+P7*Supuestos!$F$56*$J7*(Supuestos!$F$26*(Supuestos!$F$7/Supuestos!$F$6)+Supuestos!$F$27)+P7*Supuestos!$F$28*Supuestos!$F$29+(Supuestos!$F$59+Supuestos!$F$62)*$K7 -> 1721805.3 | S7: =(Supuestos!$F$35-Supuestos!$F$31)*Supuestos!$F$13*Supuestos!$F$14*$I7*(1+Supuestos!$F$15)+MIN(Supuestos!$F$35-Supuestos!$F$31,Supuestos!$F$38)*Supuestos!$F$17+((Supuestos!$F$35-Supuestos!$F$31)-MIN(Supuestos!$F$35-Supuestos!$F$31,Supuestos!$F$38))*Supuestos!$F$16 -> 2411820 | T7: =Q7-R7-S7 -> -3967532.8 | U7: =((Supuestos!$F$35)+(Supuestos!$F$36))/2*Supuestos!$F$10*Supuestos!$F$11*Supuestos!$F$12*$E7 -> 32193000 | V7: =U7*MIN(1,Supuestos!$F$42*$G7)*MIN(1,Supuestos!$F$45*$H7) -> 7340004 | W7: =U7*Supuestos!$F$48*$F7*(Supuestos!$F$7/Supuestos!$F$8*Supuestos!$F$9*$M7)+V7*(Supuestos!$F$7/Supuestos!$F$6)*(((1-Supuestos!$F$22)*Supuestos!$F$19+Supuestos!$F$22*Supuestos!$F$21)-((1-MIN(1,Supuestos!$F$51*$N7))*Supuestos!$F$19+MIN(1,Supuestos!$F$51*$N7)*Supuestos!$F$20))+V7*Supuestos!$F$23/60*Supuestos!$F$24*MIN(1,Supuestos!$F$54*$L7) -> 1773567.1 | X7: =((Supuestos!$F$35)+(Supuestos!$F$36))/2*Supuestos!$F$13*Supuestos!$F$18*12+V7*Supuestos!$F$25+V7*Supuestos!$F$57*$J7*(Supuestos!$F$26*(Supuestos!$F$7/Supuestos!$F$6)+Supuestos!$F$27)+V7*Supuestos!$F$28*Supuestos!$F$29+(Supuestos!$F$60+Supuestos!$F$63)*$K7 -> 2375080.4 | Y7: =(Supuestos!$F$36-Supuestos!$F$35)*Supuestos!$F$13*Supuestos!$F$14*$I7*(1+Supuestos!$F$15)+MIN(Supuestos!$F$36-Supuestos!$F$35,Supuestos!$F$39)*Supuestos!$F$17+((Supuestos!$F$36-Supuestos!$F$35)-MIN(Supuestos!$F$36-Supuestos!$F$35,Supuestos!$F$39))*Supuestos!$F$16 -> 1956800 | Z7: =W7-X7-Y7 -> -2558313.3 | AA7: =((Supuestos!$F$36)+(Supuestos!$F$37))/2*Supuestos!$F$10*Supuestos!$F$11*Supuestos!$F$12*$E7 -> 45271406 | AB7: =AA7*MIN(1,Supuestos!$F$43*$G7)*MIN(1,Supuestos!$F$46*$H7) -> 14486850 | AC7: =AA7*Supuestos!$F$49*$F7*(Supuestos!$F$7/Supuestos!$F$8*Supuestos!$F$9*$M7)+AB7*(Supuestos!$F$7/Supuestos!$F$6)*(((1-Supuestos!$F$22)*Supuestos!$F$19+Supuestos!$F$22*Supuestos!$F$21)-((1-MIN(1,Supuestos!$F$52*$N7))*Supuestos!$F$19+MIN(1,Supuestos!$F$52*$N7)*Supuestos!$F$20))+AB7*Supuestos!$F$23/60*Supuestos!$F$24*MIN(1,Supuestos!$F$55*$L7) -> 5104011.5 | AD7: =((Supuestos!$F$36)+(Supuestos!$F$37))/2*Supuestos!$F$13*Supuestos!$F$18*12+AB7*Supuestos!$F$25+AB7*Supuestos!$F$58*$J7*(Supuestos!$F$26*(Supuestos!$F$7/Supuestos!$F$6)+Supuestos!$F$27)+AB7*Supuestos!$F$28*Supuestos!$F$29+(Supuestos!$F$61+Supuestos!$F$64)*$K7 -> 2992534.9 | AE7: =(Supuestos!$F$37-Supuestos!$F$36)*Supuestos!$F$13*Supuestos!$F$14*$I7*(1+Supuestos!$F$15)+MIN(Supuestos!$F$37-Supuestos!$F$36,Supuestos!$F$40)*Supuestos!$F$17+((Supuestos!$F$37-Supuestos!$F$36)-MIN(Supuestos!$F$37-Supuestos!$F$36,Supuestos!$F$40))*Supuestos!$F$16 -> 1223000 | AF7: =AC7-AD7-AE7 -> 888476.61 | AG7: =((Supuestos!$F$37)+(Supuestos!$F$37))/2*Supuestos!$F$10*Supuestos!$F$11*Supuestos!$F$12*$E7 -> 50301562 | AH7: =AG7*MIN(1,Supuestos!$F$43*$G7)*MIN(1,Supuestos!$F$46*$H7) -> 16096500 | AI7: =AG7*Supuestos!$F$49*$F7*(Supuestos!$F$7/Supuestos!$F$8*Supuestos!$F$9*$M7)+AH7*(Supuestos!$F$7/Supuestos!$F$6)*(((1-Supuestos!$F$22)*Supuestos!$F$19+Supuestos!$F$22*Supuestos!$F$21)-((1-MIN(1,Supuestos!$F$52*$N7))*Supuestos!$F$19+MIN(1,Supuestos!$F$52*$N7)*Supuestos!$F$20))+AH7*Supuestos!$F$23/60*Supuestos!$F$24*MIN(1,Supuestos!$F$55*$L7) -> 5671123.9 | AJ7: =((Supuestos!$F$37)+(Supuestos!$F$37))/2*Supuestos!$F$13*Supuestos!$F$18*12+AH7*Supuestos!$F$25+AH7*Supuestos!$F$58*$J7*(Supuestos!$F$26*(Supuestos!$F$7/Supuestos!$F$6)+Supuestos!$F$27)+AH7*Supuestos!$F$28*Supuestos!$F$29+(Supuestos!$F$61+Supuestos!$F$64)*$K7 -> 3186149.9 | AK7: =0 -> 0 | AL7: =AI7-AJ7-AK7 -> 2484974 | AM7: =((Supuestos!$F$37)+(Supuestos!$F$37))/2*Supuestos!$F$10*Supuestos!$F$11*Supuestos!$F$12*$E7 -> 50301562 | AN7: =AM7*MIN(1,Supuestos!$F$43*$G7)*MIN(1,Supuestos!$F$46*$H7) -> 16096500 | AO7: =AM7*Supuestos!$F$49*$F7*(Supuestos!$F$7/Supuestos!$F$8*Supuestos!$F$9*$M7)+AN7*(Supuestos!$F$7/Supuestos!$F$6)*(((1-Supuestos!$F$22)*Supuestos!$F$19+Supuestos!$F$22*Supuestos!$F$21)-((1-MIN(1,Supuestos!$F$52*$N7))*Supuestos!$F$19+MIN(1,Supuestos!$F$52*$N7)*Supuestos!$F$20))+AN7*Supuestos!$F$23/60*Supuestos!$F$24*MIN(1,Supuestos!$F$55*$L7) -> 5671123.9 | AP7: =((Supuestos!$F$37)+(Supuestos!$F$37))/2*Supuestos!$F$13*Supuestos!$F$18*12+AN7*Supuestos!$F$25+AN7*Supuestos!$F$58*$J7*(Supuestos!$F$26*(Supuestos!$F$7/Supuestos!$F$6)+Supuestos!$F$27)+AN7*Supuestos!$F$28*Supuestos!$F$29+(Supuestos!$F$61+Supuestos!$F$64)*$K7 -> 3186149.9 | AQ7: =0 -> 0 | AR7: =AO7-AP7-AQ7 -> 2484974
A8: Volumen incr. −25 % | B8: =NPV(Supuestos!$F$30,T8,Z8,AF8,AL8,AR8) -> -4729397.9 | C8: =B8-$B$5 -> -1054935.4 | E8: 1 | F8: 0.75 | G8: 1 | H8: 1 | I8: 1 | J8: 1 | K8: 1 | L8: 1 | M8: 1 | N8: 1 | O8: =((Supuestos!$F$31)+(Supuestos!$F$35))/2*Supuestos!$F$10*Supuestos!$F$11*Supuestos!$F$12*$E8 -> 9899347.5 | P8: =O8*MIN(1,Supuestos!$F$41*$G8)*MIN(1,Supuestos!$F$44*$H8) -> 1385908.6 | Q8: =O8*Supuestos!$F$47*$F8*(Supuestos!$F$7/Supuestos!$F$8*Supuestos!$F$9*$M8)+P8*(Supuestos!$F$7/Supuestos!$F$6)*(((1-Supuestos!$F$22)*Supuestos!$F$19+Supuestos!$F$22*Supuestos!$F$21)-((1-MIN(1,Supuestos!$F$50*$N8))*Supuestos!$F$19+MIN(1,Supuestos!$F$50*$N8)*Supuestos!$F$20))+P8*Supuestos!$F$23/60*Supuestos!$F$24*MIN(1,Supuestos!$F$53*$L8) -> 94544.956 | R8: =((Supuestos!$F$31)+(Supuestos!$F$35))/2*Supuestos!$F$13*Supuestos!$F$18*12+P8*Supuestos!$F$25+P8*Supuestos!$F$56*$J8*(Supuestos!$F$26*(Supuestos!$F$7/Supuestos!$F$6)+Supuestos!$F$27)+P8*Supuestos!$F$28*Supuestos!$F$29+(Supuestos!$F$59+Supuestos!$F$62)*$K8 -> 1672536.2 | S8: =(Supuestos!$F$35-Supuestos!$F$31)*Supuestos!$F$13*Supuestos!$F$14*$I8*(1+Supuestos!$F$15)+MIN(Supuestos!$F$35-Supuestos!$F$31,Supuestos!$F$38)*Supuestos!$F$17+((Supuestos!$F$35-Supuestos!$F$31)-MIN(Supuestos!$F$35-Supuestos!$F$31,Supuestos!$F$38))*Supuestos!$F$16 -> 2411820 | T8: =Q8-R8-S8 -> -3989811.3 | U8: =((Supuestos!$F$35)+(Supuestos!$F$36))/2*Supuestos!$F$10*Supuestos!$F$11*Supuestos!$F$12*$E8 -> 25754400 | V8: =U8*MIN(1,Supuestos!$F$42*$G8)*MIN(1,Supuestos!$F$45*$H8) -> 5872003.2 | W8: =U8*Supuestos!$F$48*$F8*(Supuestos!$F$7/Supuestos!$F$8*Supuestos!$F$9*$M8)+V8*(Supuestos!$F$7/Supuestos!$F$6)*(((1-Supuestos!$F$22)*Supuestos!$F$19+Supuestos!$F$22*Supuestos!$F$21)-((1-MIN(1,Supuestos!$F$51*$N8))*Supuestos!$F$19+MIN(1,Supuestos!$F$51*$N8)*Supuestos!$F$20))+V8*Supuestos!$F$23/60*Supuestos!$F$24*MIN(1,Supuestos!$F$54*$L8) -> 1219418 | X8: =((Supuestos!$F$35)+(Supuestos!$F$36))/2*Supuestos!$F$13*Supuestos!$F$18*12+V8*Supuestos!$F$25+V8*Supuestos!$F$57*$J8*(Supuestos!$F$26*(Supuestos!$F$7/Supuestos!$F$6)+Supuestos!$F$27)+V8*Supuestos!$F$28*Supuestos!$F$29+(Supuestos!$F$60+Supuestos!$F$63)*$K8 -> 2225344.3 | Y8: =(Supuestos!$F$36-Supuestos!$F$35)*Supuestos!$F$13*Supuestos!$F$14*$I8*(1+Supuestos!$F$15)+MIN(Supuestos!$F$36-Supuestos!$F$35,Supuestos!$F$39)*Supuestos!$F$17+((Supuestos!$F$36-Supuestos!$F$35)-MIN(Supuestos!$F$36-Supuestos!$F$35,Supuestos!$F$39))*Supuestos!$F$16 -> 1956800 | Z8: =W8-X8-Y8 -> -2962726.3 | AA8: =((Supuestos!$F$36)+(Supuestos!$F$37))/2*Supuestos!$F$10*Supuestos!$F$11*Supuestos!$F$12*$E8 -> 36217125 | AB8: =AA8*MIN(1,Supuestos!$F$43*$G8)*MIN(1,Supuestos!$F$46*$H8) -> 11589480 | AC8: =AA8*Supuestos!$F$49*$F8*(Supuestos!$F$7/Supuestos!$F$8*Supuestos!$F$9*$M8)+AB8*(Supuestos!$F$7/Supuestos!$F$6)*(((1-Supuestos!$F$22)*Supuestos!$F$19+Supuestos!$F$22*Supuestos!$F$21)-((1-MIN(1,Supuestos!$F$52*$N8))*Supuestos!$F$19+MIN(1,Supuestos!$F$52*$N8)*Supuestos!$F$20))+AB8*Supuestos!$F$23/60*Supuestos!$F$24*MIN(1,Supuestos!$F$55*$L8) -> 3662524.7 | AD8: =((Supuestos!$F$36)+(Supuestos!$F$37))/2*Supuestos!$F$13*Supuestos!$F$18*12+AB8*Supuestos!$F$25+AB8*Supuestos!$F$58*$J8*(Supuestos!$F$26*(Supuestos!$F$7/Supuestos!$F$6)+Supuestos!$F$27)+AB8*Supuestos!$F$28*Supuestos!$F$29+(Supuestos!$F$61+Supuestos!$F$64)*$K8 -> 2735827.9 | AE8: =(Supuestos!$F$37-Supuestos!$F$36)*Supuestos!$F$13*Supuestos!$F$14*$I8*(1+Supuestos!$F$15)+MIN(Supuestos!$F$37-Supuestos!$F$36,Supuestos!$F$40)*Supuestos!$F$17+((Supuestos!$F$37-Supuestos!$F$36)-MIN(Supuestos!$F$37-Supuestos!$F$36,Supuestos!$F$40))*Supuestos!$F$16 -> 1223000 | AF8: =AC8-AD8-AE8 -> -296303.26 | AG8: =((Supuestos!$F$37)+(Supuestos!$F$37))/2*Supuestos!$F$10*Supuestos!$F$11*Supuestos!$F$12*$E8 -> 40241250 | AH8: =AG8*MIN(1,Supuestos!$F$43*$G8)*MIN(1,Supuestos!$F$46*$H8) -> 12877200 | AI8: =AG8*Supuestos!$F$49*$F8*(Supuestos!$F$7/Supuestos!$F$8*Supuestos!$F$9*$M8)+AH8*(Supuestos!$F$7/Supuestos!$F$6)*(((1-Supuestos!$F$22)*Supuestos!$F$19+Supuestos!$F$22*Supuestos!$F$21)-((1-MIN(1,Supuestos!$F$52*$N8))*Supuestos!$F$19+MIN(1,Supuestos!$F$52*$N8)*Supuestos!$F$20))+AH8*Supuestos!$F$23/60*Supuestos!$F$24*MIN(1,Supuestos!$F$55*$L8) -> 4069471.9 | AJ8: =((Supuestos!$F$37)+(Supuestos!$F$37))/2*Supuestos!$F$13*Supuestos!$F$18*12+AH8*Supuestos!$F$25+AH8*Supuestos!$F$58*$J8*(Supuestos!$F$26*(Supuestos!$F$7/Supuestos!$F$6)+Supuestos!$F$27)+AH8*Supuestos!$F$28*Supuestos!$F$29+(Supuestos!$F$61+Supuestos!$F$64)*$K8 -> 2900919.9 | AK8: =0 -> 0 | AL8: =AI8-AJ8-AK8 -> 1168551.9 | AM8: =((Supuestos!$F$37)+(Supuestos!$F$37))/2*Supuestos!$F$10*Supuestos!$F$11*Supuestos!$F$12*$E8 -> 40241250 | AN8: =AM8*MIN(1,Supuestos!$F$43*$G8)*MIN(1,Supuestos!$F$46*$H8) -> 12877200 | AO8: =AM8*Supuestos!$F$49*$F8*(Supuestos!$F$7/Supuestos!$F$8*Supuestos!$F$9*$M8)+AN8*(Supuestos!$F$7/Supuestos!$F$6)*(((1-Supuestos!$F$22)*Supuestos!$F$19+Supuestos!$F$22*Supuestos!$F$21)-((1-MIN(1,Supuestos!$F$52*$N8))*Supuestos!$F$19+MIN(1,Supuestos!$F$52*$N8)*Supuestos!$F$20))+AN8*Supuestos!$F$23/60*Supuestos!$F$24*MIN(1,Supuestos!$F$55*$L8) -> 4069471.9 | AP8: =((Supuestos!$F$37)+(Supuestos!$F$37))/2*Supuestos!$F$13*Supuestos!$F$18*12+AN8*Supuestos!$F$25+AN8*Supuestos!$F$58*$J8*(Supuestos!$F$26*(Supuestos!$F$7/Supuestos!$F$6)+Supuestos!$F$27)+AN8*Supuestos!$F$28*Supuestos!$F$29+(Supuestos!$F$61+Supuestos!$F$64)*$K8 -> 2900919.9 | AQ8: =0 -> 0 | AR8: =AO8-AP8-AQ8 -> 1168551.9
A9: Volumen incr. +25 % | B9: =NPV(Supuestos!$F$30,T9,Z9,AF9,AL9,AR9) -> -2619527 | C9: =B9-$B$5 -> 1054935.4 | E9: 1 | F9: 1.25 | G9: 1 | H9: 1 | I9: 1 | J9: 1 | K9: 1 | L9: 1 | M9: 1 | N9: 1 | O9: =((Supuestos!$F$31)+(Supuestos!$F$35))/2*Supuestos!$F$10*Supuestos!$F$11*Supuestos!$F$12*$E9 -> 9899347.5 | P9: =O9*MIN(1,Supuestos!$F$41*$G9)*MIN(1,Supuestos!$F$44*$H9) -> 1385908.6 | Q9: =O9*Supuestos!$F$47*$F9*(Supuestos!$F$7/Supuestos!$F$8*Supuestos!$F$9*$M9)+P9*(Supuestos!$F$7/Supuestos!$F$6)*(((1-Supuestos!$F$22)*Supuestos!$F$19+Supuestos!$F$22*Supuestos!$F$21)-((1-MIN(1,Supuestos!$F$50*$N9))*Supuestos!$F$19+MIN(1,Supuestos!$F$50*$N9)*Supuestos!$F$20))+P9*Supuestos!$F$23/60*Supuestos!$F$24*MIN(1,Supuestos!$F$53*$L9) -> 171203.03 | R9: =((Supuestos!$F$31)+(Supuestos!$F$35))/2*Supuestos!$F$13*Supuestos!$F$18*12+P9*Supuestos!$F$25+P9*Supuestos!$F$56*$J9*(Supuestos!$F$26*(Supuestos!$F$7/Supuestos!$F$6)+Supuestos!$F$27)+P9*Supuestos!$F$28*Supuestos!$F$29+(Supuestos!$F$59+Supuestos!$F$62)*$K9 -> 1672536.2 | S9: =(Supuestos!$F$35-Supuestos!$F$31)*Supuestos!$F$13*Supuestos!$F$14*$I9*(1+Supuestos!$F$15)+MIN(Supuestos!$F$35-Supuestos!$F$31,Supuestos!$F$38)*Supuestos!$F$17+((Supuestos!$F$35-Supuestos!$F$31)-MIN(Supuestos!$F$35-Supuestos!$F$31,Supuestos!$F$38))*Supuestos!$F$16 -> 2411820 | T9: =Q9-R9-S9 -> -3913153.2 | U9: =((Supuestos!$F$35)+(Supuestos!$F$36))/2*Supuestos!$F$10*Supuestos!$F$11*Supuestos!$F$12*$E9 -> 25754400 | V9: =U9*MIN(1,Supuestos!$F$42*$G9)*MIN(1,Supuestos!$F$45*$H9) -> 5872003.2 | W9: =U9*Supuestos!$F$48*$F9*(Supuestos!$F$7/Supuestos!$F$8*Supuestos!$F$9*$M9)+V9*(Supuestos!$F$7/Supuestos!$F$6)*(((1-Supuestos!$F$22)*Supuestos!$F$19+Supuestos!$F$22*Supuestos!$F$21)-((1-MIN(1,Supuestos!$F$51*$N9))*Supuestos!$F$19+MIN(1,Supuestos!$F$51*$N9)*Supuestos!$F$20))+V9*Supuestos!$F$23/60*Supuestos!$F$24*MIN(1,Supuestos!$F$54*$L9) -> 1618289.3 | X9: =((Supuestos!$F$35)+(Supuestos!$F$36))/2*Supuestos!$F$13*Supuestos!$F$18*12+V9*Supuestos!$F$25+V9*Supuestos!$F$57*$J9*(Supuestos!$F$26*(Supuestos!$F$7/Supuestos!$F$6)+Supuestos!$F$27)+V9*Supuestos!$F$28*Supuestos!$F$29+(Supuestos!$F$60+Supuestos!$F$63)*$K9 -> 2225344.3 | Y9: =(Supuestos!$F$36-Supuestos!$F$35)*Supuestos!$F$13*Supuestos!$F$14*$I9*(1+Supuestos!$F$15)+MIN(Supuestos!$F$36-Supuestos!$F$35,Supuestos!$F$39)*Supuestos!$F$17+((Supuestos!$F$36-Supuestos!$F$35)-MIN(Supuestos!$F$36-Supuestos!$F$35,Supuestos!$F$39))*Supuestos!$F$16 -> 1956800 | Z9: =W9-X9-Y9 -> -2563855 | AA9: =((Supuestos!$F$36)+(Supuestos!$F$37))/2*Supuestos!$F$10*Supuestos!$F$11*Supuestos!$F$12*$E9 -> 36217125 | AB9: =AA9*MIN(1,Supuestos!$F$43*$G9)*MIN(1,Supuestos!$F$46*$H9) -> 11589480 | AC9: =AA9*Supuestos!$F$49*$F9*(Supuestos!$F$7/Supuestos!$F$8*Supuestos!$F$9*$M9)+AB9*(Supuestos!$F$7/Supuestos!$F$6)*(((1-Supuestos!$F$22)*Supuestos!$F$19+Supuestos!$F$22*Supuestos!$F$21)-((1-MIN(1,Supuestos!$F$52*$N9))*Supuestos!$F$19+MIN(1,Supuestos!$F$52*$N9)*Supuestos!$F$20))+AB9*Supuestos!$F$23/60*Supuestos!$F$24*MIN(1,Supuestos!$F$55*$L9) -> 4503893.8 | AD9: =((Supuestos!$F$36)+(Supuestos!$F$37))/2*Supuestos!$F$13*Supuestos!$F$18*12+AB9*Supuestos!$F$25+AB9*Supuestos!$F$58*$J9*(Supuestos!$F$26*(Supuestos!$F$7/Supuestos!$F$6)+Supuestos!$F$27)+AB9*Supuestos!$F$28*Supuestos!$F$29+(Supuestos!$F$61+Supuestos!$F$64)*$K9 -> 2735827.9 | AE9: =(Supuestos!$F$37-Supuestos!$F$36)*Supuestos!$F$13*Supuestos!$F$14*$I9*(1+Supuestos!$F$15)+MIN(Supuestos!$F$37-Supuestos!$F$36,Supuestos!$F$40)*Supuestos!$F$17+((Supuestos!$F$37-Supuestos!$F$36)-MIN(Supuestos!$F$37-Supuestos!$F$36,Supuestos!$F$40))*Supuestos!$F$16 -> 1223000 | AF9: =AC9-AD9-AE9 -> 545065.83 | AG9: =((Supuestos!$F$37)+(Supuestos!$F$37))/2*Supuestos!$F$10*Supuestos!$F$11*Supuestos!$F$12*$E9 -> 40241250 | AH9: =AG9*MIN(1,Supuestos!$F$43*$G9)*MIN(1,Supuestos!$F$46*$H9) -> 12877200 | AI9: =AG9*Supuestos!$F$49*$F9*(Supuestos!$F$7/Supuestos!$F$8*Supuestos!$F$9*$M9)+AH9*(Supuestos!$F$7/Supuestos!$F$6)*(((1-Supuestos!$F$22)*Supuestos!$F$19+Supuestos!$F$22*Supuestos!$F$21)-((1-MIN(1,Supuestos!$F$52*$N9))*Supuestos!$F$19+MIN(1,Supuestos!$F$52*$N9)*Supuestos!$F$20))+AH9*Supuestos!$F$23/60*Supuestos!$F$24*MIN(1,Supuestos!$F$55*$L9) -> 5004326.4 | AJ9: =((Supuestos!$F$37)+(Supuestos!$F$37))/2*Supuestos!$F$13*Supuestos!$F$18*12+AH9*Supuestos!$F$25+AH9*Supuestos!$F$58*$J9*(Supuestos!$F$26*(Supuestos!$F$7/Supuestos!$F$6)+Supuestos!$F$27)+AH9*Supuestos!$F$28*Supuestos!$F$29+(Supuestos!$F$61+Supuestos!$F$64)*$K9 -> 2900919.9 | AK9: =0 -> 0 | AL9: =AI9-AJ9-AK9 -> 2103406.5 | AM9: =((Supuestos!$F$37)+(Supuestos!$F$37))/2*Supuestos!$F$10*Supuestos!$F$11*Supuestos!$F$12*$E9 -> 40241250 | AN9: =AM9*MIN(1,Supuestos!$F$43*$G9)*MIN(1,Supuestos!$F$46*$H9) -> 12877200 | AO9: =AM9*Supuestos!$F$49*$F9*(Supuestos!$F$7/Supuestos!$F$8*Supuestos!$F$9*$M9)+AN9*(Supuestos!$F$7/Supuestos!$F$6)*(((1-Supuestos!$F$22)*Supuestos!$F$19+Supuestos!$F$22*Supuestos!$F$21)-((1-MIN(1,Supuestos!$F$52*$N9))*Supuestos!$F$19+MIN(1,Supuestos!$F$52*$N9)*Supuestos!$F$20))+AN9*Supuestos!$F$23/60*Supuestos!$F$24*MIN(1,Supuestos!$F$55*$L9) -> 5004326.4 | AP9: =((Supuestos!$F$37)+(Supuestos!$F$37))/2*Supuestos!$F$13*Supuestos!$F$18*12+AN9*Supuestos!$F$25+AN9*Supuestos!$F$58*$J9*(Supuestos!$F$26*(Supuestos!$F$7/Supuestos!$F$6)+Supuestos!$F$27)+AN9*Supuestos!$F$28*Supuestos!$F$29+(Supuestos!$F$61+Supuestos!$F$64)*$K9 -> 2900919.9 | AQ9: =0 -> 0 | AR9: =AO9-AP9-AQ9 -> 2103406.5
A10: Enrolamiento −25 % | B10: =NPV(Supuestos!$F$30,T10,Z10,AF10,AL10,AR10) -> -4333764.8 | C10: =B10-$B$5 -> -659302.35 | E10: 1 | F10: 1 | G10: 0.75 | H10: 1 | I10: 1 | J10: 1 | K10: 1 | L10: 1 | M10: 1 | N10: 1 | O10: =((Supuestos!$F$31)+(Supuestos!$F$35))/2*Supuestos!$F$10*Supuestos!$F$11*Supuestos!$F$12*$E10 -> 9899347.5 | P10: =O10*MIN(1,Supuestos!$F$41*$G10)*MIN(1,Supuestos!$F$44*$H10) -> 1039431.5 | Q10: =O10*Supuestos!$F$47*$F10*(Supuestos!$F$7/Supuestos!$F$8*Supuestos!$F$9*$M10)+P10*(Supuestos!$F$7/Supuestos!$F$6)*(((1-Supuestos!$F$22)*Supuestos!$F$19+Supuestos!$F$22*Supuestos!$F$21)-((1-MIN(1,Supuestos!$F$50*$N10))*Supuestos!$F$19+MIN(1,Supuestos!$F$50*$N10)*Supuestos!$F$20))+P10*Supuestos!$F$23/60*Supuestos!$F$24*MIN(1,Supuestos!$F$53*$L10) -> 137984.53 | R10: =((Supuestos!$F$31)+(Supuestos!$F$35))/2*Supuestos!$F$13*Supuestos!$F$18*12+P10*Supuestos!$F$25+P10*Supuestos!$F$56*$J10*(Supuestos!$F$26*(Supuestos!$F$7/Supuestos!$F$6)+Supuestos!$F$27)+P10*Supuestos!$F$28*Supuestos!$F$29+(Supuestos!$F$59+Supuestos!$F$62)*$K10 -> 1623267.2 | S10: =(Supuestos!$F$35-Supuestos!$F$31)*Supuestos!$F$13*Supuestos!$F$14*$I10*(1+Supuestos!$F$15)+MIN(Supuestos!$F$35-Supuestos!$F$31,Supuestos!$F$38)*Supuestos!$F$17+((Supuestos!$F$35-Supuestos!$F$31)-MIN(Supuestos!$F$35-Supuestos!$F$31,Supuestos!$F$38))*Supuestos!$F$16 -> 2411820 | T10: =Q10-R10-S10 -> -3897102.6 | U10: =((Supuestos!$F$35)+(Supuestos!$F$36))/2*Supuestos!$F$10*Supuestos!$F$11*Supuestos!$F$12*$E10 -> 25754400 | V10: =U10*MIN(1,Supuestos!$F$42*$G10)*MIN(1,Supuestos!$F$45*$H10) -> 4404002.4 | W10: =U10*Supuestos!$F$48*$F10*(Supuestos!$F$7/Supuestos!$F$8*Supuestos!$F$9*$M10)+V10*(Supuestos!$F$7/Supuestos!$F$6)*(((1-Supuestos!$F$22)*Supuestos!$F$19+Supuestos!$F$22*Supuestos!$F$21)-((1-MIN(1,Supuestos!$F$51*$N10))*Supuestos!$F$19+MIN(1,Supuestos!$F$51*$N10)*Supuestos!$F$20))+V10*Supuestos!$F$23/60*Supuestos!$F$24*MIN(1,Supuestos!$F$54*$L10) -> 1263575.9 | X10: =((Supuestos!$F$35)+(Supuestos!$F$36))/2*Supuestos!$F$13*Supuestos!$F$18*12+V10*Supuestos!$F$25+V10*Supuestos!$F$57*$J10*(Supuestos!$F$26*(Supuestos!$F$7/Supuestos!$F$6)+Supuestos!$F$27)+V10*Supuestos!$F$28*Supuestos!$F$29+(Supuestos!$F$60+Supuestos!$F$63)*$K10 -> 2075608.2 | Y10: =(Supuestos!$F$36-Supuestos!$F$35)*Supuestos!$F$13*Supuestos!$F$14*$I10*(1+Supuestos!$F$15)+MIN(Supuestos!$F$36-Supuestos!$F$35,Supuestos!$F$39)*Supuestos!$F$17+((Supuestos!$F$36-Supuestos!$F$35)-MIN(Supuestos!$F$36-Supuestos!$F$35,Supuestos!$F$39))*Supuestos!$F$16 -> 1956800 | Z10: =W10-X10-Y10 -> -2768832.4 | AA10: =((Supuestos!$F$36)+(Supuestos!$F$37))/2*Supuestos!$F$10*Supuestos!$F$11*Supuestos!$F$12*$E10 -> 36217125 | AB10: =AA10*MIN(1,Supuestos!$F$43*$G10)*MIN(1,Supuestos!$F$46*$H10) -> 8692110 | AC10: =AA10*Supuestos!$F$49*$F10*(Supuestos!$F$7/Supuestos!$F$8*Supuestos!$F$9*$M10)+AB10*(Supuestos!$F$7/Supuestos!$F$6)*(((1-Supuestos!$F$22)*Supuestos!$F$19+Supuestos!$F$22*Supuestos!$F$21)-((1-MIN(1,Supuestos!$F$52*$N10))*Supuestos!$F$19+MIN(1,Supuestos!$F$52*$N10)*Supuestos!$F$20))+AB10*Supuestos!$F$23/60*Supuestos!$F$24*MIN(1,Supuestos!$F$55*$L10) -> 3483091.5 | AD10: =((Supuestos!$F$36)+(Supuestos!$F$37))/2*Supuestos!$F$13*Supuestos!$F$18*12+AB10*Supuestos!$F$25+AB10*Supuestos!$F$58*$J10*(Supuestos!$F$26*(Supuestos!$F$7/Supuestos!$F$6)+Supuestos!$F$27)+AB10*Supuestos!$F$28*Supuestos!$F$29+(Supuestos!$F$61+Supuestos!$F$64)*$K10 -> 2479120.9 | AE10: =(Supuestos!$F$37-Supuestos!$F$36)*Supuestos!$F$13*Supuestos!$F$14*$I10*(1+Supuestos!$F$15)+MIN(Supuestos!$F$37-Supuestos!$F$36,Supuestos!$F$40)*Supuestos!$F$17+((Supuestos!$F$37-Supuestos!$F$36)-MIN(Supuestos!$F$37-Supuestos!$F$36,Supuestos!$F$40))*Supuestos!$F$16 -> 1223000 | AF10: =AC10-AD10-AE10 -> -219029.49 | AG10: =((Supuestos!$F$37)+(Supuestos!$F$37))/2*Supuestos!$F$10*Supuestos!$F$11*Supuestos!$F$12*$E10 -> 40241250 | AH10: =AG10*MIN(1,Supuestos!$F$43*$G10)*MIN(1,Supuestos!$F$46*$H10) -> 9657900 | AI10: =AG10*Supuestos!$F$49*$F10*(Supuestos!$F$7/Supuestos!$F$8*Supuestos!$F$9*$M10)+AH10*(Supuestos!$F$7/Supuestos!$F$6)*(((1-Supuestos!$F$22)*Supuestos!$F$19+Supuestos!$F$22*Supuestos!$F$21)-((1-MIN(1,Supuestos!$F$52*$N10))*Supuestos!$F$19+MIN(1,Supuestos!$F$52*$N10)*Supuestos!$F$20))+AH10*Supuestos!$F$23/60*Supuestos!$F$24*MIN(1,Supuestos!$F$55*$L10) -> 3870101.6 | AJ10: =((Supuestos!$F$37)+(Supuestos!$F$37))/2*Supuestos!$F$13*Supuestos!$F$18*12+AH10*Supuestos!$F$25+AH10*Supuestos!$F$58*$J10*(Supuestos!$F$26*(Supuestos!$F$7/Supuestos!$F$6)+Supuestos!$F$27)+AH10*Supuestos!$F$28*Supuestos!$F$29+(Supuestos!$F$61+Supuestos!$F$64)*$K10 -> 2615689.9 | AK10: =0 -> 0 | AL10: =AI10-AJ10-AK10 -> 1254411.7 | AM10: =((Supuestos!$F$37)+(Supuestos!$F$37))/2*Supuestos!$F$10*Supuestos!$F$11*Supuestos!$F$12*$E10 -> 40241250 | AN10: =AM10*MIN(1,Supuestos!$F$43*$G10)*MIN(1,Supuestos!$F$46*$H10) -> 9657900 | AO10: =AM10*Supuestos!$F$49*$F10*(Supuestos!$F$7/Supuestos!$F$8*Supuestos!$F$9*$M10)+AN10*(Supuestos!$F$7/Supuestos!$F$6)*(((1-Supuestos!$F$22)*Supuestos!$F$19+Supuestos!$F$22*Supuestos!$F$21)-((1-MIN(1,Supuestos!$F$52*$N10))*Supuestos!$F$19+MIN(1,Supuestos!$F$52*$N10)*Supuestos!$F$20))+AN10*Supuestos!$F$23/60*Supuestos!$F$24*MIN(1,Supuestos!$F$55*$L10) -> 3870101.6 | AP10: =((Supuestos!$F$37)+(Supuestos!$F$37))/2*Supuestos!$F$13*Supuestos!$F$18*12+AN10*Supuestos!$F$25+AN10*Supuestos!$F$58*$J10*(Supuestos!$F$26*(Supuestos!$F$7/Supuestos!$F$6)+Supuestos!$F$27)+AN10*Supuestos!$F$28*Supuestos!$F$29+(Supuestos!$F$61+Supuestos!$F$64)*$K10 -> 2615689.9 | AQ10: =0 -> 0 | AR10: =AO10-AP10-AQ10 -> 1254411.7
A11: Enrolamiento +25 % | B11: =NPV(Supuestos!$F$30,T11,Z11,AF11,AL11,AR11) -> -3015160.1 | C11: =B11-$B$5 -> 659302.35 | E11: 1 | F11: 1 | G11: 1.25 | H11: 1 | I11: 1 | J11: 1 | K11: 1 | L11: 1 | M11: 1 | N11: 1 | O11: =((Supuestos!$F$31)+(Supuestos!$F$35))/2*Supuestos!$F$10*Supuestos!$F$11*Supuestos!$F$12*$E11 -> 9899347.5 | P11: =O11*MIN(1,Supuestos!$F$41*$G11)*MIN(1,Supuestos!$F$44*$H11) -> 1732385.8 | Q11: =O11*Supuestos!$F$47*$F11*(Supuestos!$F$7/Supuestos!$F$8*Supuestos!$F$9*$M11)+P11*(Supuestos!$F$7/Supuestos!$F$6)*(((1-Supuestos!$F$22)*Supuestos!$F$19+Supuestos!$F$22*Supuestos!$F$21)-((1-MIN(1,Supuestos!$F$50*$N11))*Supuestos!$F$19+MIN(1,Supuestos!$F$50*$N11)*Supuestos!$F$20))+P11*Supuestos!$F$23/60*Supuestos!$F$24*MIN(1,Supuestos!$F$53*$L11) -> 127763.45 | R11: =((Supuestos!$F$31)+(Supuestos!$F$35))/2*Supuestos!$F$13*Supuestos!$F$18*12+P11*Supuestos!$F$25+P11*Supuestos!$F$56*$J11*(Supuestos!$F$26*(Supuestos!$F$7/Supuestos!$F$6)+Supuestos!$F$27)+P11*Supuestos!$F$28*Supuestos!$F$29+(Supuestos!$F$59+Supuestos!$F$62)*$K11 -> 1721805.3 | S11: =(Supuestos!$F$35-Supuestos!$F$31)*Supuestos!$F$13*Supuestos!$F$14*$I11*(1+Supuestos!$F$15)+MIN(Supuestos!$F$35-Supuestos!$F$31,Supuestos!$F$38)*Supuestos!$F$17+((Supuestos!$F$35-Supuestos!$F$31)-MIN(Supuestos!$F$35-Supuestos!$F$31,Supuestos!$F$38))*Supuestos!$F$16 -> 2411820 | T11: =Q11-R11-S11 -> -4005861.8 | U11: =((Supuestos!$F$35)+(Supuestos!$F$36))/2*Supuestos!$F$10*Supuestos!$F$11*Supuestos!$F$12*$E11 -> 25754400 | V11: =U11*MIN(1,Supuestos!$F$42*$G11)*MIN(1,Supuestos!$F$45*$H11) -> 7340004 | W11: =U11*Supuestos!$F$48*$F11*(Supuestos!$F$7/Supuestos!$F$8*Supuestos!$F$9*$M11)+V11*(Supuestos!$F$7/Supuestos!$F$6)*(((1-Supuestos!$F$22)*Supuestos!$F$19+Supuestos!$F$22*Supuestos!$F$21)-((1-MIN(1,Supuestos!$F$51*$N11))*Supuestos!$F$19+MIN(1,Supuestos!$F$51*$N11)*Supuestos!$F$20))+V11*Supuestos!$F$23/60*Supuestos!$F$24*MIN(1,Supuestos!$F$54*$L11) -> 1574131.5 | X11: =((Supuestos!$F$35)+(Supuestos!$F$36))/2*Supuestos!$F$13*Supuestos!$F$18*12+V11*Supuestos!$F$25+V11*Supuestos!$F$57*$J11*(Supuestos!$F$26*(Supuestos!$F$7/Supuestos!$F$6)+Supuestos!$F$27)+V11*Supuestos!$F$28*Supuestos!$F$29+(Supuestos!$F$60+Supuestos!$F$63)*$K11 -> 2375080.4 | Y11: =(Supuestos!$F$36-Supuestos!$F$35)*Supuestos!$F$13*Supuestos!$F$14*$I11*(1+Supuestos!$F$15)+MIN(Supuestos!$F$36-Supuestos!$F$35,Supuestos!$F$39)*Supuestos!$F$17+((Supuestos!$F$36-Supuestos!$F$35)-MIN(Supuestos!$F$36-Supuestos!$F$35,Supuestos!$F$39))*Supuestos!$F$16 -> 1956800 | Z11: =W11-X11-Y11 -> -2757748.9 | AA11: =((Supuestos!$F$36)+(Supuestos!$F$37))/2*Supuestos!$F$10*Supuestos!$F$11*Supuestos!$F$12*$E11 -> 36217125 | AB11: =AA11*MIN(1,Supuestos!$F$43*$G11)*MIN(1,Supuestos!$F$46*$H11) -> 14486850 | AC11: =AA11*Supuestos!$F$49*$F11*(Supuestos!$F$7/Supuestos!$F$8*Supuestos!$F$9*$M11)+AB11*(Supuestos!$F$7/Supuestos!$F$6)*(((1-Supuestos!$F$22)*Supuestos!$F$19+Supuestos!$F$22*Supuestos!$F$21)-((1-MIN(1,Supuestos!$F$52*$N11))*Supuestos!$F$19+MIN(1,Supuestos!$F$52*$N11)*Supuestos!$F$20))+AB11*Supuestos!$F$23/60*Supuestos!$F$24*MIN(1,Supuestos!$F$55*$L11) -> 4683327 | AD11: =((Supuestos!$F$36)+(Supuestos!$F$37))/2*Supuestos!$F$13*Supuestos!$F$18*12+AB11*Supuestos!$F$25+AB11*Supuestos!$F$58*$J11*(Supuestos!$F$26*(Supuestos!$F$7/Supuestos!$F$6)+Supuestos!$F$27)+AB11*Supuestos!$F$28*Supuestos!$F$29+(Supuestos!$F$61+Supuestos!$F$64)*$K11 -> 2992534.9 | AE11: =(Supuestos!$F$37-Supuestos!$F$36)*Supuestos!$F$13*Supuestos!$F$14*$I11*(1+Supuestos!$F$15)+MIN(Supuestos!$F$37-Supuestos!$F$36,Supuestos!$F$40)*Supuestos!$F$17+((Supuestos!$F$37-Supuestos!$F$36)-MIN(Supuestos!$F$37-Supuestos!$F$36,Supuestos!$F$40))*Supuestos!$F$16 -> 1223000 | AF11: =AC11-AD11-AE11 -> 467792.07 | AG11: =((Supuestos!$F$37)+(Supuestos!$F$37))/2*Supuestos!$F$10*Supuestos!$F$11*Supuestos!$F$12*$E11 -> 40241250 | AH11: =AG11*MIN(1,Supuestos!$F$43*$G11)*MIN(1,Supuestos!$F$46*$H11) -> 16096500 | AI11: =AG11*Supuestos!$F$49*$F11*(Supuestos!$F$7/Supuestos!$F$8*Supuestos!$F$9*$M11)+AH11*(Supuestos!$F$7/Supuestos!$F$6)*(((1-Supuestos!$F$22)*Supuestos!$F$19+Supuestos!$F$22*Supuestos!$F$21)-((1-MIN(1,Supuestos!$F$52*$N11))*Supuestos!$F$19+MIN(1,Supuestos!$F$52*$N11)*Supuestos!$F$20))+AH11*Supuestos!$F$23/60*Supuestos!$F$24*MIN(1,Supuestos!$F$55*$L11) -> 5203696.6 | AJ11: =((Supuestos!$F$37)+(Supuestos!$F$37))/2*Supuestos!$F$13*Supuestos!$F$18*12+AH11*Supuestos!$F$25+AH11*Supuestos!$F$58*$J11*(Supuestos!$F$26*(Supuestos!$F$7/Supuestos!$F$6)+Supuestos!$F$27)+AH11*Supuestos!$F$28*Supuestos!$F$29+(Supuestos!$F$61+Supuestos!$F$64)*$K11 -> 3186149.9 | AK11: =0 -> 0 | AL11: =AI11-AJ11-AK11 -> 2017546.7 | AM11: =((Supuestos!$F$37)+(Supuestos!$F$37))/2*Supuestos!$F$10*Supuestos!$F$11*Supuestos!$F$12*$E11 -> 40241250 | AN11: =AM11*MIN(1,Supuestos!$F$43*$G11)*MIN(1,Supuestos!$F$46*$H11) -> 16096500 | AO11: =AM11*Supuestos!$F$49*$F11*(Supuestos!$F$7/Supuestos!$F$8*Supuestos!$F$9*$M11)+AN11*(Supuestos!$F$7/Supuestos!$F$6)*(((1-Supuestos!$F$22)*Supuestos!$F$19+Supuestos!$F$22*Supuestos!$F$21)-((1-MIN(1,Supuestos!$F$52*$N11))*Supuestos!$F$19+MIN(1,Supuestos!$F$52*$N11)*Supuestos!$F$20))+AN11*Supuestos!$F$23/60*Supuestos!$F$24*MIN(1,Supuestos!$F$55*$L11) -> 5203696.6 | AP11: =((Supuestos!$F$37)+(Supuestos!$F$37))/2*Supuestos!$F$13*Supuestos!$F$18*12+AN11*Supuestos!$F$25+AN11*Supuestos!$F$58*$J11*(Supuestos!$F$26*(Supuestos!$F$7/Supuestos!$F$6)+Supuestos!$F$27)+AN11*Supuestos!$F$28*Supuestos!$F$29+(Supuestos!$F$61+Supuestos!$F$64)*$K11 -> 3186149.9 | AQ11: =0 -> 0 | AR11: =AO11-AP11-AQ11 -> 2017546.7
